Internal Server Error: /admin/login/
Traceback (most recent call last):
  File "C:\Users\lovem\AppData\Local\Programs\Python\Python313\Lib\site-packages\django\db\backends\utils.py", line 105, in _execute
    return self.cursor.execute(sql, params)
           ~~~~~~~~~~~~~~~~~~~^^^^^^^^^^^^^
  File "C:\Users\lovem\AppData\Local\Programs\Python\Python313\Lib\site-packages\django\db\backends\sqlite3\base.py", line 354, in execute
    return super().execute(query, params)
           ~~~~~~~~~~~~~~~^^^^^^^^^^^^^^^
sqlite3.OperationalError: no such table: auth_user

The above exception was the direct cause of the following exception:

Traceback (most recent call last):
  File "C:\Users\lovem\AppData\Local\Programs\Python\Python313\Lib\site-packages\django\core\handlers\exception.py", line 55, in inner
    response = get_response(request)
  File "C:\Users\lovem\AppData\Local\Programs\Python\Python313\Lib\site-packages\django\core\handlers\base.py", line 197, in _get_response
    response = wrapped_callback(request, *callback_args, **callback_kwargs)
  File "C:\Users\lovem\AppData\Local\Programs\Python\Python313\Lib\site-packages\django\utils\decorators.py", line 48, in _wrapper
    return bound_method(*args, **kwargs)
  File "C:\Users\lovem\AppData\Local\Programs\Python\Python313\Lib\site-packages\django\views\decorators\cache.py", line 80, in _view_wrapper
    response = view_func(request, *args, **kwargs)
  File "C:\Users\lovem\AppData\Local\Programs\Python\Python313\Lib\site-packages\django\contrib\admin\sites.py", line 444, in login
    return LoginView.as_view(**defaults)(request)
           ~~~~~~~~~~~~~~~~~~~~~~~~~~~~~^^^^^^^^^
  File "C:\Users\lovem\AppData\Local\Programs\Python\Python313\Lib\site-packages\django\views\generic\base.py", line 104, in view
    return self.dispatch(request, *args, **kwargs)
           ~~~~~~~~~~~~~^^^^^^^^^^^^^^^^^^^^^^^^^^
  File "C:\Users\lovem\AppData\Local\Programs\Python\Python313\Lib\site-packages\django\utils\decorators.py", line 48, in _wrapper
    return bound_method(*args, **kwargs)
  File "C:\Users\lovem\AppData\Local\Programs\Python\Python313\Lib\site-packages\django\utils\decorators.py", line 48, in _wrapper
    return bound_method(*args, **kwargs)
  File "C:\Users\lovem\AppData\Local\Programs\Python\Python313\Lib\site-packages\django\views\decorators\debug.py", line 143, in sensitive_post_parameters_wrapper
    return view(request, *args, **kwargs)
  File "C:\Users\lovem\AppData\Local\Programs\Python\Python313\Lib\site-packages\django\utils\decorators.py", line 48, in _wrapper
    return bound_method(*args, **kwargs)
  File "C:\Users\lovem\AppData\Local\Programs\Python\Python313\Lib\site-packages\django\utils\decorators.py", line 188, in _view_wrapper
    result = _process_exception(request, e)
  File "C:\Users\lovem\AppData\Local\Programs\Python\Python313\Lib\site-packages\django\utils\decorators.py", line 186, in _view_wrapper
    response = view_func(request, *args, **kwargs)
  File "C:\Users\lovem\AppData\Local\Programs\Python\Python313\Lib\site-packages\django\utils\decorators.py", line 48, in _wrapper
    return bound_method(*args, **kwargs)
  File "C:\Users\lovem\AppData\Local\Programs\Python\Python313\Lib\site-packages\django\views\decorators\cache.py", line 80, in _view_wrapper
    response = view_func(request, *args, **kwargs)
  File "C:\Users\lovem\AppData\Local\Programs\Python\Python313\Lib\site-packages\django\contrib\auth\views.py", line 89, in dispatch
    return super().dispatch(request, *args, **kwargs)
           ~~~~~~~~~~~~~~~~^^^^^^^^^^^^^^^^^^^^^^^^^^
  File "C:\Users\lovem\AppData\Local\Programs\Python\Python313\Lib\site-packages\django\views\generic\base.py", line 143, in dispatch
    return handler(request, *args, **kwargs)
  File "C:\Users\lovem\AppData\Local\Programs\Python\Python313\Lib\site-packages\django\views\generic\edit.py", line 150, in post
    if form.is_valid():
       ~~~~~~~~~~~~~^^
  File "C:\Users\lovem\AppData\Local\Programs\Python\Python313\Lib\site-packages\django\forms\forms.py", line 197, in is_valid
    return self.is_bound and not self.errors
                                 ^^^^^^^^^^^
  File "C:\Users\lovem\AppData\Local\Programs\Python\Python313\Lib\site-packages\django\forms\forms.py", line 192, in errors
    self.full_clean()
    ~~~~~~~~~~~~~~~^^
  File "C:\Users\lovem\AppData\Local\Programs\Python\Python313\Lib\site-packages\django\forms\forms.py", line 326, in full_clean
    self._clean_form()
    ~~~~~~~~~~~~~~~~^^
  File "C:\Users\lovem\AppData\Local\Programs\Python\Python313\Lib\site-packages\django\forms\forms.py", line 342, in _clean_form
    cleaned_data = self.clean()
  File "C:\Users\lovem\AppData\Local\Programs\Python\Python313\Lib\site-packages\django\contrib\auth\forms.py", line 356, in clean
    self.user_cache = authenticate(
                      ~~~~~~~~~~~~^
        self.request, username=username, password=password
        ^^^^^^^^^^^^^^^^^^^^^^^^^^^^^^^^^^^^^^^^^^^^^^^^^^
    )
    ^
  File "C:\Users\lovem\AppData\Local\Programs\Python\Python313\Lib\site-packages\django\views\decorators\debug.py", line 75, in sensitive_variables_wrapper
    return func(*func_args, **func_kwargs)
  File "C:\Users\lovem\AppData\Local\Programs\Python\Python313\Lib\site-packages\django\contrib\auth\__init__.py", line 79, in authenticate
    user = backend.authenticate(request, **credentials)
  File "C:\Users\lovem\AppData\Local\Programs\Python\Python313\Lib\site-packages\django\contrib\auth\backends.py", line 42, in authenticate
    user = UserModel._default_manager.get_by_natural_key(username)
  File "C:\Users\lovem\AppData\Local\Programs\Python\Python313\Lib\site-packages\django\contrib\auth\base_user.py", line 37, in get_by_natural_key
    return self.get(**{self.model.USERNAME_FIELD: username})
           ~~~~~~~~^^^^^^^^^^^^^^^^^^^^^^^^^^^^^^^^^^^^^^^^^
  File "C:\Users\lovem\AppData\Local\Programs\Python\Python313\Lib\site-packages\django\db\models\manager.py", line 87, in manager_method
    return getattr(self.get_queryset(), name)(*args, **kwargs)
           ~~~~~~~~~~~~~~~~~~~~~~~~~~~~~~~~~~^^^^^^^^^^^^^^^^^
  File "C:\Users\lovem\AppData\Local\Programs\Python\Python313\Lib\site-packages\django\db\models\query.py", line 645, in get
    num = len(clone)
  File "C:\Users\lovem\AppData\Local\Programs\Python\Python313\Lib\site-packages\django\db\models\query.py", line 382, in __len__
    self._fetch_all()
    ~~~~~~~~~~~~~~~^^
  File "C:\Users\lovem\AppData\Local\Programs\Python\Python313\Lib\site-packages\django\db\models\query.py", line 1928, in _fetch_all
    self._result_cache = list(self._iterable_class(self))
                         ~~~~^^^^^^^^^^^^^^^^^^^^^^^^^^^^
  File "C:\Users\lovem\AppData\Local\Programs\Python\Python313\Lib\site-packages\django\db\models\query.py", line 91, in __iter__
    results = compiler.execute_sql(
        chunked_fetch=self.chunked_fetch, chunk_size=self.chunk_size
    )
  File "C:\Users\lovem\AppData\Local\Programs\Python\Python313\Lib\site-packages\django\db\models\sql\compiler.py", line 1574, in execute_sql
    cursor.execute(sql, params)
    ~~~~~~~~~~~~~~^^^^^^^^^^^^^
  File "C:\Users\lovem\AppData\Local\Programs\Python\Python313\Lib\site-packages\django\db\backends\utils.py", line 122, in execute
    return super().execute(sql, params)
           ~~~~~~~~~~~~~~~^^^^^^^^^^^^^
  File "C:\Users\lovem\AppData\Local\Programs\Python\Python313\Lib\site-packages\django\db\backends\utils.py", line 79, in execute
    return self._execute_with_wrappers(
           ~~~~~~~~~~~~~~~~~~~~~~~~~~~^
        sql, params, many=False, executor=self._execute
        ^^^^^^^^^^^^^^^^^^^^^^^^^^^^^^^^^^^^^^^^^^^^^^^
    )
    ^
  File "C:\Users\lovem\AppData\Local\Programs\Python\Python313\Lib\site-packages\django\db\backends\utils.py", line 92, in _execute_with_wrappers
    return executor(sql, params, many, context)
  File "C:\Users\lovem\AppData\Local\Programs\Python\Python313\Lib\site-packages\django\db\backends\utils.py", line 100, in _execute
    with self.db.wrap_database_errors:
         ^^^^^^^^^^^^^^^^^^^^^^^^^^^^
  File "C:\Users\lovem\AppData\Local\Programs\Python\Python313\Lib\site-packages\django\db\utils.py", line 91, in __exit__
    raise dj_exc_value.with_traceback(traceback) from exc_value
  File "C:\Users\lovem\AppData\Local\Programs\Python\Python313\Lib\site-packages\django\db\backends\utils.py", line 105, in _execute
    return self.cursor.execute(sql, params)
           ~~~~~~~~~~~~~~~~~~~^^^^^^^^^^^^^
  File "C:\Users\lovem\AppData\Local\Programs\Python\Python313\Lib\site-packages\django\db\backends\sqlite3\base.py", line 354, in execute
    return super().execute(query, params)
           ~~~~~~~~~~~~~~~^^^^^^^^^^^^^^^
django.db.utils.OperationalError: no such table: auth_user
"POST /admin/login/?next=/admin/ HTTP/1.1" 500 256012
Internal Server Error: /get-zipcode/
Traceback (most recent call last):
  File "C:\Users\Sulaiman\AppData\Local\Programs\Python\Python311\Lib\site-packages\django\db\models\fields\__init__.py", line 2123, in get_prep_value
    return int(value)
           ^^^^^^^^^^
ValueError: invalid literal for int() with base 10: ''

The above exception was the direct cause of the following exception:

Traceback (most recent call last):
  File "C:\Users\Sulaiman\AppData\Local\Programs\Python\Python311\Lib\site-packages\django\core\handlers\exception.py", line 55, in inner
    response = get_response(request)
               ^^^^^^^^^^^^^^^^^^^^^
  File "C:\Users\Sulaiman\AppData\Local\Programs\Python\Python311\Lib\site-packages\django\core\handlers\base.py", line 197, in _get_response
    response = wrapped_callback(request, *callback_args, **callback_kwargs)
               ^^^^^^^^^^^^^^^^^^^^^^^^^^^^^^^^^^^^^^^^^^^^^^^^^^^^^^^^^^^^
  File "C:\Users\Sulaiman\Desktop\New folder (2)\student-result\students\views.py", line 106, in get_zipcode
    subdistrict = Tambon.objects.filter(id=subdistrict_id).first()
                  ^^^^^^^^^^^^^^^^^^^^^^^^^^^^^^^^^^^^^^^^
  File "C:\Users\Sulaiman\AppData\Local\Programs\Python\Python311\Lib\site-packages\django\db\models\manager.py", line 87, in manager_method
    return getattr(self.get_queryset(), name)(*args, **kwargs)
           ^^^^^^^^^^^^^^^^^^^^^^^^^^^^^^^^^^^^^^^^^^^^^^^^^^^
  File "C:\Users\Sulaiman\AppData\Local\Programs\Python\Python311\Lib\site-packages\django\db\models\query.py", line 1476, in filter
    return self._filter_or_exclude(False, args, kwargs)
           ^^^^^^^^^^^^^^^^^^^^^^^^^^^^^^^^^^^^^^^^^^^^
  File "C:\Users\Sulaiman\AppData\Local\Programs\Python\Python311\Lib\site-packages\django\db\models\query.py", line 1494, in _filter_or_exclude
    clone._filter_or_exclude_inplace(negate, args, kwargs)
  File "C:\Users\Sulaiman\AppData\Local\Programs\Python\Python311\Lib\site-packages\django\db\models\query.py", line 1501, in _filter_or_exclude_inplace
    self._query.add_q(Q(*args, **kwargs))
  File "C:\Users\Sulaiman\AppData\Local\Programs\Python\Python311\Lib\site-packages\django\db\models\sql\query.py", line 1609, in add_q
    clause, _ = self._add_q(q_object, self.used_aliases)
                ^^^^^^^^^^^^^^^^^^^^^^^^^^^^^^^^^^^^^^^^
  File "C:\Users\Sulaiman\AppData\Local\Programs\Python\Python311\Lib\site-packages\django\db\models\sql\query.py", line 1641, in _add_q
    child_clause, needed_inner = self.build_filter(
                                 ^^^^^^^^^^^^^^^^^^
  File "C:\Users\Sulaiman\AppData\Local\Programs\Python\Python311\Lib\site-packages\django\db\models\sql\query.py", line 1555, in build_filter
    condition = self.build_lookup(lookups, col, value)
                ^^^^^^^^^^^^^^^^^^^^^^^^^^^^^^^^^^^^^^
  File "C:\Users\Sulaiman\AppData\Local\Programs\Python\Python311\Lib\site-packages\django\db\models\sql\query.py", line 1385, in build_lookup
    lookup = lookup_class(lhs, rhs)
             ^^^^^^^^^^^^^^^^^^^^^^
  File "C:\Users\Sulaiman\AppData\Local\Programs\Python\Python311\Lib\site-packages\django\db\models\lookups.py", line 30, in __init__
    self.rhs = self.get_prep_lookup()
               ^^^^^^^^^^^^^^^^^^^^^^
  File "C:\Users\Sulaiman\AppData\Local\Programs\Python\Python311\Lib\site-packages\django\db\models\lookups.py", line 369, in get_prep_lookup
    return super().get_prep_lookup()
           ^^^^^^^^^^^^^^^^^^^^^^^^^
  File "C:\Users\Sulaiman\AppData\Local\Programs\Python\Python311\Lib\site-packages\django\db\models\lookups.py", line 88, in get_prep_lookup
    return self.lhs.output_field.get_prep_value(self.rhs)
           ^^^^^^^^^^^^^^^^^^^^^^^^^^^^^^^^^^^^^^^^^^^^^^
  File "C:\Users\Sulaiman\AppData\Local\Programs\Python\Python311\Lib\site-packages\django\db\models\fields\__init__.py", line 2125, in get_prep_value
    raise e.__class__(
ValueError: Field 'id' expected a number but got ''.
"GET /get-zipcode/?subdistrict_id= HTTP/1.1" 500 145297
Internal Server Error: /get-zipcode/
Traceback (most recent call last):
  File "C:\Users\Sulaiman\AppData\Local\Programs\Python\Python311\Lib\site-packages\django\db\models\fields\__init__.py", line 2123, in get_prep_value
    return int(value)
           ^^^^^^^^^^
ValueError: invalid literal for int() with base 10: ''

The above exception was the direct cause of the following exception:

Traceback (most recent call last):
  File "C:\Users\Sulaiman\AppData\Local\Programs\Python\Python311\Lib\site-packages\django\core\handlers\exception.py", line 55, in inner
    response = get_response(request)
               ^^^^^^^^^^^^^^^^^^^^^
  File "C:\Users\Sulaiman\AppData\Local\Programs\Python\Python311\Lib\site-packages\django\core\handlers\base.py", line 197, in _get_response
    response = wrapped_callback(request, *callback_args, **callback_kwargs)
               ^^^^^^^^^^^^^^^^^^^^^^^^^^^^^^^^^^^^^^^^^^^^^^^^^^^^^^^^^^^^
  File "C:\Users\Sulaiman\Desktop\New folder (2)\student-result\students\views.py", line 106, in get_zipcode
    subdistrict = Tambon.objects.filter(id=subdistrict_id).first()
                  ^^^^^^^^^^^^^^^^^^^^^^^^^^^^^^^^^^^^^^^^
  File "C:\Users\Sulaiman\AppData\Local\Programs\Python\Python311\Lib\site-packages\django\db\models\manager.py", line 87, in manager_method
    return getattr(self.get_queryset(), name)(*args, **kwargs)
           ^^^^^^^^^^^^^^^^^^^^^^^^^^^^^^^^^^^^^^^^^^^^^^^^^^^
  File "C:\Users\Sulaiman\AppData\Local\Programs\Python\Python311\Lib\site-packages\django\db\models\query.py", line 1476, in filter
    return self._filter_or_exclude(False, args, kwargs)
           ^^^^^^^^^^^^^^^^^^^^^^^^^^^^^^^^^^^^^^^^^^^^
  File "C:\Users\Sulaiman\AppData\Local\Programs\Python\Python311\Lib\site-packages\django\db\models\query.py", line 1494, in _filter_or_exclude
    clone._filter_or_exclude_inplace(negate, args, kwargs)
  File "C:\Users\Sulaiman\AppData\Local\Programs\Python\Python311\Lib\site-packages\django\db\models\query.py", line 1501, in _filter_or_exclude_inplace
    self._query.add_q(Q(*args, **kwargs))
  File "C:\Users\Sulaiman\AppData\Local\Programs\Python\Python311\Lib\site-packages\django\db\models\sql\query.py", line 1609, in add_q
    clause, _ = self._add_q(q_object, self.used_aliases)
                ^^^^^^^^^^^^^^^^^^^^^^^^^^^^^^^^^^^^^^^^
  File "C:\Users\Sulaiman\AppData\Local\Programs\Python\Python311\Lib\site-packages\django\db\models\sql\query.py", line 1641, in _add_q
    child_clause, needed_inner = self.build_filter(
                                 ^^^^^^^^^^^^^^^^^^
  File "C:\Users\Sulaiman\AppData\Local\Programs\Python\Python311\Lib\site-packages\django\db\models\sql\query.py", line 1555, in build_filter
    condition = self.build_lookup(lookups, col, value)
                ^^^^^^^^^^^^^^^^^^^^^^^^^^^^^^^^^^^^^^
  File "C:\Users\Sulaiman\AppData\Local\Programs\Python\Python311\Lib\site-packages\django\db\models\sql\query.py", line 1385, in build_lookup
    lookup = lookup_class(lhs, rhs)
             ^^^^^^^^^^^^^^^^^^^^^^
  File "C:\Users\Sulaiman\AppData\Local\Programs\Python\Python311\Lib\site-packages\django\db\models\lookups.py", line 30, in __init__
    self.rhs = self.get_prep_lookup()
               ^^^^^^^^^^^^^^^^^^^^^^
  File "C:\Users\Sulaiman\AppData\Local\Programs\Python\Python311\Lib\site-packages\django\db\models\lookups.py", line 369, in get_prep_lookup
    return super().get_prep_lookup()
           ^^^^^^^^^^^^^^^^^^^^^^^^^
  File "C:\Users\Sulaiman\AppData\Local\Programs\Python\Python311\Lib\site-packages\django\db\models\lookups.py", line 88, in get_prep_lookup
    return self.lhs.output_field.get_prep_value(self.rhs)
           ^^^^^^^^^^^^^^^^^^^^^^^^^^^^^^^^^^^^^^^^^^^^^^
  File "C:\Users\Sulaiman\AppData\Local\Programs\Python\Python311\Lib\site-packages\django\db\models\fields\__init__.py", line 2125, in get_prep_value
    raise e.__class__(
ValueError: Field 'id' expected a number but got ''.
"GET /get-zipcode/?subdistrict_id= HTTP/1.1" 500 145297
Internal Server Error: /in_profile/
Traceback (most recent call last):
  File "C:\Users\Sulaiman\AppData\Local\Programs\Python\Python311\Lib\site-packages\django\db\backends\utils.py", line 105, in _execute
    return self.cursor.execute(sql, params)
           ^^^^^^^^^^^^^^^^^^^^^^^^^^^^^^^^
  File "C:\Users\Sulaiman\AppData\Local\Programs\Python\Python311\Lib\site-packages\django\db\backends\sqlite3\base.py", line 354, in execute
    return super().execute(query, params)
           ^^^^^^^^^^^^^^^^^^^^^^^^^^^^^^
sqlite3.IntegrityError: UNIQUE constraint failed: students_student.id_number

The above exception was the direct cause of the following exception:

Traceback (most recent call last):
  File "C:\Users\Sulaiman\AppData\Local\Programs\Python\Python311\Lib\site-packages\django\core\handlers\exception.py", line 55, in inner
    response = get_response(request)
               ^^^^^^^^^^^^^^^^^^^^^
  File "C:\Users\Sulaiman\AppData\Local\Programs\Python\Python311\Lib\site-packages\django\core\handlers\base.py", line 197, in _get_response
    response = wrapped_callback(request, *callback_args, **callback_kwargs)
               ^^^^^^^^^^^^^^^^^^^^^^^^^^^^^^^^^^^^^^^^^^^^^^^^^^^^^^^^^^^^
  File "C:\Users\Sulaiman\Desktop\New folder (2)\student-result\students\views.py", line 324, in Input_Profile
    student = Student.objects.create(
              ^^^^^^^^^^^^^^^^^^^^^^^
  File "C:\Users\Sulaiman\AppData\Local\Programs\Python\Python311\Lib\site-packages\django\db\models\manager.py", line 87, in manager_method
    return getattr(self.get_queryset(), name)(*args, **kwargs)
           ^^^^^^^^^^^^^^^^^^^^^^^^^^^^^^^^^^^^^^^^^^^^^^^^^^^
  File "C:\Users\Sulaiman\AppData\Local\Programs\Python\Python311\Lib\site-packages\django\db\models\query.py", line 679, in create
    obj.save(force_insert=True, using=self.db)
  File "C:\Users\Sulaiman\Desktop\New folder (2)\student-result\students\models.py", line 159, in save
    super().save(*args, **kwargs)
  File "C:\Users\Sulaiman\AppData\Local\Programs\Python\Python311\Lib\site-packages\django\db\models\base.py", line 891, in save
    self.save_base(
  File "C:\Users\Sulaiman\AppData\Local\Programs\Python\Python311\Lib\site-packages\django\db\models\base.py", line 997, in save_base
    updated = self._save_table(
              ^^^^^^^^^^^^^^^^^
  File "C:\Users\Sulaiman\AppData\Local\Programs\Python\Python311\Lib\site-packages\django\db\models\base.py", line 1160, in _save_table
    results = self._do_insert(
              ^^^^^^^^^^^^^^^^
  File "C:\Users\Sulaiman\AppData\Local\Programs\Python\Python311\Lib\site-packages\django\db\models\base.py", line 1201, in _do_insert
    return manager._insert(
           ^^^^^^^^^^^^^^^^
  File "C:\Users\Sulaiman\AppData\Local\Programs\Python\Python311\Lib\site-packages\django\db\models\manager.py", line 87, in manager_method
    return getattr(self.get_queryset(), name)(*args, **kwargs)
           ^^^^^^^^^^^^^^^^^^^^^^^^^^^^^^^^^^^^^^^^^^^^^^^^^^^
  File "C:\Users\Sulaiman\AppData\Local\Programs\Python\Python311\Lib\site-packages\django\db\models\query.py", line 1847, in _insert
    return query.get_compiler(using=using).execute_sql(returning_fields)
           ^^^^^^^^^^^^^^^^^^^^^^^^^^^^^^^^^^^^^^^^^^^^^^^^^^^^^^^^^^^^^
  File "C:\Users\Sulaiman\AppData\Local\Programs\Python\Python311\Lib\site-packages\django\db\models\sql\compiler.py", line 1836, in execute_sql
    cursor.execute(sql, params)
  File "C:\Users\Sulaiman\AppData\Local\Programs\Python\Python311\Lib\site-packages\django\db\backends\utils.py", line 122, in execute
    return super().execute(sql, params)
           ^^^^^^^^^^^^^^^^^^^^^^^^^^^^
  File "C:\Users\Sulaiman\AppData\Local\Programs\Python\Python311\Lib\site-packages\django\db\backends\utils.py", line 79, in execute
    return self._execute_with_wrappers(
           ^^^^^^^^^^^^^^^^^^^^^^^^^^^^
  File "C:\Users\Sulaiman\AppData\Local\Programs\Python\Python311\Lib\site-packages\django\db\backends\utils.py", line 92, in _execute_with_wrappers
    return executor(sql, params, many, context)
           ^^^^^^^^^^^^^^^^^^^^^^^^^^^^^^^^^^^^
  File "C:\Users\Sulaiman\AppData\Local\Programs\Python\Python311\Lib\site-packages\django\db\backends\utils.py", line 100, in _execute
    with self.db.wrap_database_errors:
  File "C:\Users\Sulaiman\AppData\Local\Programs\Python\Python311\Lib\site-packages\django\db\utils.py", line 91, in __exit__
    raise dj_exc_value.with_traceback(traceback) from exc_value
  File "C:\Users\Sulaiman\AppData\Local\Programs\Python\Python311\Lib\site-packages\django\db\backends\utils.py", line 105, in _execute
    return self.cursor.execute(sql, params)
           ^^^^^^^^^^^^^^^^^^^^^^^^^^^^^^^^
  File "C:\Users\Sulaiman\AppData\Local\Programs\Python\Python311\Lib\site-packages\django\db\backends\sqlite3\base.py", line 354, in execute
    return super().execute(query, params)
           ^^^^^^^^^^^^^^^^^^^^^^^^^^^^^^
django.db.utils.IntegrityError: UNIQUE constraint failed: students_student.id_number
"POST /in_profile/ HTTP/1.1" 500 199288
Internal Server Error: /ingr_student
Traceback (most recent call last):
  File "C:\Users\Sulaiman\AppData\Local\Programs\Python\Python311\Lib\site-packages\django\core\handlers\exception.py", line 55, in inner
    response = get_response(request)
               ^^^^^^^^^^^^^^^^^^^^^
  File "C:\Users\Sulaiman\AppData\Local\Programs\Python\Python311\Lib\site-packages\django\core\handlers\base.py", line 197, in _get_response
    response = wrapped_callback(request, *callback_args, **callback_kwargs)
               ^^^^^^^^^^^^^^^^^^^^^^^^^^^^^^^^^^^^^^^^^^^^^^^^^^^^^^^^^^^^
  File "C:\Users\Sulaiman\Desktop\New folder (2)\student-result\students\views.py", line 618, in student_marks_view
    current_year = int(current_semester.year)
                       ^^^^^^^^^^^^^^^^
UnboundLocalError: cannot access local variable 'current_semester' where it is not associated with a value
"GET /ingr_student?school=%E0%B8%AD%E0%B8%B4%E0%B8%AA%E0%B8%A5%E0%B8%B2%E0%B8%A1%E0%B8%B5%E0%B8%A2%E0%B8%B0%E0%B8%AE%E0%B9%8C&level=%E0%B8%A3%E0%B8%B0%E0%B8%94%E0%B8%B1%E0%B8%9A%E0%B8%8A%E0%B8%B1%E0%B9%89%E0%B8%99%E0%B8%9B%E0%B8%B5+1&semester=2 HTTP/1.1" 500 81208
Internal Server Error: /ingr_student
Traceback (most recent call last):
  File "C:\Users\Sulaiman\AppData\Local\Programs\Python\Python311\Lib\site-packages\django\core\handlers\exception.py", line 55, in inner
    response = get_response(request)
               ^^^^^^^^^^^^^^^^^^^^^
  File "C:\Users\Sulaiman\AppData\Local\Programs\Python\Python311\Lib\site-packages\django\core\handlers\base.py", line 197, in _get_response
    response = wrapped_callback(request, *callback_args, **callback_kwargs)
               ^^^^^^^^^^^^^^^^^^^^^^^^^^^^^^^^^^^^^^^^^^^^^^^^^^^^^^^^^^^^
  File "C:\Users\Sulaiman\Desktop\New folder (2)\student-result\students\views.py", line 618, in student_marks_view
    if current_semester:
       ^^^^^^^^^^^^^^^^
UnboundLocalError: cannot access local variable 'current_semester' where it is not associated with a value
"GET /ingr_student?school=%E0%B8%AD%E0%B8%B4%E0%B8%AA%E0%B8%A5%E0%B8%B2%E0%B8%A1%E0%B8%B5%E0%B8%A2%E0%B8%B0%E0%B8%AE%E0%B9%8C&level=%E0%B8%A3%E0%B8%B0%E0%B8%94%E0%B8%B1%E0%B8%9A%E0%B8%8A%E0%B8%B1%E0%B9%89%E0%B8%99%E0%B8%9B%E0%B8%B5+1&semester=2 HTTP/1.1" 500 81319
Internal Server Error: /ingr_student
Traceback (most recent call last):
  File "C:\Users\Sulaiman\AppData\Local\Programs\Python\Python311\Lib\site-packages\django\core\handlers\exception.py", line 55, in inner
    response = get_response(request)
               ^^^^^^^^^^^^^^^^^^^^^
  File "C:\Users\Sulaiman\AppData\Local\Programs\Python\Python311\Lib\site-packages\django\core\handlers\base.py", line 197, in _get_response
    response = wrapped_callback(request, *callback_args, **callback_kwargs)
               ^^^^^^^^^^^^^^^^^^^^^^^^^^^^^^^^^^^^^^^^^^^^^^^^^^^^^^^^^^^^
  File "C:\Users\Sulaiman\Desktop\New folder (2)\student-result\students\views.py", line 618, in student_marks_view
    if current_semester:
       ^^^^^^^^^^^^^^^^
UnboundLocalError: cannot access local variable 'current_semester' where it is not associated with a value
"GET /ingr_student?school=%E0%B8%AD%E0%B8%B4%E0%B8%AA%E0%B8%A5%E0%B8%B2%E0%B8%A1%E0%B8%B5%E0%B8%A2%E0%B8%B0%E0%B8%AE%E0%B9%8C&level=%E0%B8%A3%E0%B8%B0%E0%B8%94%E0%B8%B1%E0%B8%9A%E0%B8%8A%E0%B8%B1%E0%B9%89%E0%B8%99%E0%B8%9B%E0%B8%B5+1&semester=2 HTTP/1.1" 500 81319
Internal Server Error: /ingr_student
Traceback (most recent call last):
  File "C:\Users\Sulaiman\AppData\Local\Programs\Python\Python311\Lib\site-packages\django\core\handlers\exception.py", line 55, in inner
    response = get_response(request)
               ^^^^^^^^^^^^^^^^^^^^^
  File "C:\Users\Sulaiman\AppData\Local\Programs\Python\Python311\Lib\site-packages\django\core\handlers\base.py", line 197, in _get_response
    response = wrapped_callback(request, *callback_args, **callback_kwargs)
               ^^^^^^^^^^^^^^^^^^^^^^^^^^^^^^^^^^^^^^^^^^^^^^^^^^^^^^^^^^^^
  File "C:\Users\Sulaiman\Desktop\New folder (2)\student-result\students\views.py", line 618, in student_marks_view
    if current_semester:
       ^^^^^^^^^^^^^^^^
UnboundLocalError: cannot access local variable 'current_semester' where it is not associated with a value
"GET /ingr_student?school=%E0%B8%AD%E0%B8%B4%E0%B8%AA%E0%B8%A5%E0%B8%B2%E0%B8%A1%E0%B8%B5%E0%B8%A2%E0%B8%B0%E0%B8%AE%E0%B9%8C&level=%E0%B8%A3%E0%B8%B0%E0%B8%94%E0%B8%B1%E0%B8%9A%E0%B8%8A%E0%B8%B1%E0%B9%89%E0%B8%99%E0%B8%9B%E0%B8%B5+1&semester=2 HTTP/1.1" 500 81319
Internal Server Error: /ingr_student
Traceback (most recent call last):
  File "C:\Users\Sulaiman\AppData\Local\Programs\Python\Python311\Lib\site-packages\django\core\handlers\exception.py", line 55, in inner
    response = get_response(request)
               ^^^^^^^^^^^^^^^^^^^^^
  File "C:\Users\Sulaiman\AppData\Local\Programs\Python\Python311\Lib\site-packages\django\core\handlers\base.py", line 197, in _get_response
    response = wrapped_callback(request, *callback_args, **callback_kwargs)
               ^^^^^^^^^^^^^^^^^^^^^^^^^^^^^^^^^^^^^^^^^^^^^^^^^^^^^^^^^^^^
  File "C:\Users\Sulaiman\Desktop\New folder (2)\student-result\students\views.py", line 618, in student_marks_view
    if current_semester:
       ^^^^^^^^^^^^^^^^
UnboundLocalError: cannot access local variable 'current_semester' where it is not associated with a value
"GET /ingr_student?school=%E0%B8%AD%E0%B8%B4%E0%B8%AA%E0%B8%A5%E0%B8%B2%E0%B8%A1%E0%B8%B5%E0%B8%A2%E0%B8%B0%E0%B8%AE%E0%B9%8C&level=%E0%B8%A3%E0%B8%B0%E0%B8%94%E0%B8%B1%E0%B8%9A%E0%B8%8A%E0%B8%B1%E0%B9%89%E0%B8%99%E0%B8%9B%E0%B8%B5+1&semester=2 HTTP/1.1" 500 81319
Internal Server Error: /ingr_student
Traceback (most recent call last):
  File "C:\Users\Sulaiman\AppData\Local\Programs\Python\Python311\Lib\site-packages\django\core\handlers\exception.py", line 55, in inner
    response = get_response(request)
               ^^^^^^^^^^^^^^^^^^^^^
  File "C:\Users\Sulaiman\AppData\Local\Programs\Python\Python311\Lib\site-packages\django\core\handlers\base.py", line 197, in _get_response
    response = wrapped_callback(request, *callback_args, **callback_kwargs)
               ^^^^^^^^^^^^^^^^^^^^^^^^^^^^^^^^^^^^^^^^^^^^^^^^^^^^^^^^^^^^
  File "C:\Users\Sulaiman\Desktop\New folder (2)\student-result\students\views.py", line 618, in student_marks_view
    if current_semester:
       ^^^^^^^^^^^^^^^^
UnboundLocalError: cannot access local variable 'current_semester' where it is not associated with a value
"GET /ingr_student?school=%E0%B8%AD%E0%B8%B4%E0%B8%AA%E0%B8%A5%E0%B8%B2%E0%B8%A1%E0%B8%B5%E0%B8%A2%E0%B8%B0%E0%B8%AE%E0%B9%8C&level=%E0%B8%A3%E0%B8%B0%E0%B8%94%E0%B8%B1%E0%B8%9A%E0%B8%8A%E0%B8%B1%E0%B9%89%E0%B8%99%E0%B8%9B%E0%B8%B5+1&semester=2 HTTP/1.1" 500 81182
Internal Server Error: /ingr_student
Traceback (most recent call last):
  File "C:\Users\Sulaiman\AppData\Local\Programs\Python\Python311\Lib\site-packages\django\core\handlers\exception.py", line 55, in inner
    response = get_response(request)
               ^^^^^^^^^^^^^^^^^^^^^
  File "C:\Users\Sulaiman\AppData\Local\Programs\Python\Python311\Lib\site-packages\django\core\handlers\base.py", line 197, in _get_response
    response = wrapped_callback(request, *callback_args, **callback_kwargs)
               ^^^^^^^^^^^^^^^^^^^^^^^^^^^^^^^^^^^^^^^^^^^^^^^^^^^^^^^^^^^^
  File "C:\Users\Sulaiman\Desktop\New folder (2)\student-result\students\views.py", line 618, in student_marks_view
    if current_semester:
       ^^^^^^^^^^^^^^^^
UnboundLocalError: cannot access local variable 'current_semester' where it is not associated with a value
"GET /ingr_student HTTP/1.1" 500 79146
Internal Server Error: /ingr_student
Traceback (most recent call last):
  File "C:\Users\Sulaiman\AppData\Local\Programs\Python\Python311\Lib\site-packages\django\core\handlers\exception.py", line 55, in inner
    response = get_response(request)
               ^^^^^^^^^^^^^^^^^^^^^
  File "C:\Users\Sulaiman\AppData\Local\Programs\Python\Python311\Lib\site-packages\django\core\handlers\base.py", line 197, in _get_response
    response = wrapped_callback(request, *callback_args, **callback_kwargs)
               ^^^^^^^^^^^^^^^^^^^^^^^^^^^^^^^^^^^^^^^^^^^^^^^^^^^^^^^^^^^^
  File "C:\Users\Sulaiman\Desktop\New folder (2)\student-result\students\views.py", line 618, in student_marks_view
    if current_semester:
       ^^^^^^^^^^^^^^^^
UnboundLocalError: cannot access local variable 'current_semester' where it is not associated with a value
"GET /ingr_student HTTP/1.1" 500 79146
Internal Server Error: /gr_student
Traceback (most recent call last):
  File "C:\Users\Sulaiman\AppData\Local\Programs\Python\Python311\Lib\site-packages\django\core\handlers\exception.py", line 55, in inner
    response = get_response(request)
               ^^^^^^^^^^^^^^^^^^^^^
  File "C:\Users\Sulaiman\AppData\Local\Programs\Python\Python311\Lib\site-packages\django\core\handlers\base.py", line 197, in _get_response
    response = wrapped_callback(request, *callback_args, **callback_kwargs)
               ^^^^^^^^^^^^^^^^^^^^^^^^^^^^^^^^^^^^^^^^^^^^^^^^^^^^^^^^^^^^
  File "C:\Users\Sulaiman\Desktop\New folder (2)\student-result\students\views.py", line 793, in GR_Student
    semester_selected = request.GET.get('semester', current_semester.semester if current_semester else None)
                                                                                 ^^^^^^^^^^^^^^^^
UnboundLocalError: cannot access local variable 'current_semester' where it is not associated with a value
"GET /gr_student HTTP/1.1" 500 79901
Internal Server Error: /student_results/688010001/
Traceback (most recent call last):
  File "C:\Users\Sulaiman\AppData\Local\Programs\Python\Python311\Lib\site-packages\django\core\handlers\exception.py", line 55, in inner
    response = get_response(request)
               ^^^^^^^^^^^^^^^^^^^^^
  File "C:\Users\Sulaiman\AppData\Local\Programs\Python\Python311\Lib\site-packages\django\core\handlers\base.py", line 197, in _get_response
    response = wrapped_callback(request, *callback_args, **callback_kwargs)
               ^^^^^^^^^^^^^^^^^^^^^^^^^^^^^^^^^^^^^^^^^^^^^^^^^^^^^^^^^^^^
  File "C:\Users\Sulaiman\Desktop\New folder (2)\student-result\students\views.py", line 985, in student_Results
    semester = request.GET.get('semester') or (current_semester.semester if current_semester else 1)
                                                                            ^^^^^^^^^^^^^^^^
UnboundLocalError: cannot access local variable 'current_semester' where it is not associated with a value
"GET /student_results/688010001/ HTTP/1.1" 500 79951
Internal Server Error: /student_results/688010001/
Traceback (most recent call last):
  File "C:\Users\Sulaiman\AppData\Local\Programs\Python\Python311\Lib\site-packages\django\core\handlers\exception.py", line 55, in inner
    response = get_response(request)
               ^^^^^^^^^^^^^^^^^^^^^
  File "C:\Users\Sulaiman\AppData\Local\Programs\Python\Python311\Lib\site-packages\django\core\handlers\base.py", line 197, in _get_response
    response = wrapped_callback(request, *callback_args, **callback_kwargs)
               ^^^^^^^^^^^^^^^^^^^^^^^^^^^^^^^^^^^^^^^^^^^^^^^^^^^^^^^^^^^^
  File "C:\Users\Sulaiman\Desktop\New folder (2)\student-result\students\views.py", line 985, in student_Results
    semester = request.GET.get('semester') or (current_semester.semester if current_semester else 1)
                                                                            ^^^^^^^^^^^^^^^^
UnboundLocalError: cannot access local variable 'current_semester' where it is not associated with a value
"GET /student_results/688010001/ HTTP/1.1" 500 79951
Internal Server Error: /student_results/688010001/
Traceback (most recent call last):
  File "C:\Users\Sulaiman\AppData\Local\Programs\Python\Python311\Lib\site-packages\django\core\handlers\exception.py", line 55, in inner
    response = get_response(request)
               ^^^^^^^^^^^^^^^^^^^^^
  File "C:\Users\Sulaiman\AppData\Local\Programs\Python\Python311\Lib\site-packages\django\core\handlers\base.py", line 197, in _get_response
    response = wrapped_callback(request, *callback_args, **callback_kwargs)
               ^^^^^^^^^^^^^^^^^^^^^^^^^^^^^^^^^^^^^^^^^^^^^^^^^^^^^^^^^^^^
  File "C:\Users\Sulaiman\Desktop\New folder (2)\student-result\students\views.py", line 985, in student_Results
    semester = request.GET.get('semester') or (current_semester.semester if current_semester else 1)
                                                                            ^^^^^^^^^^^^^^^^
UnboundLocalError: cannot access local variable 'current_semester' where it is not associated with a value
"GET /student_results/688010001/ HTTP/1.1" 500 79951
Internal Server Error: /student_results/688010001/
Traceback (most recent call last):
  File "C:\Users\Sulaiman\AppData\Local\Programs\Python\Python311\Lib\site-packages\django\core\handlers\exception.py", line 55, in inner
    response = get_response(request)
               ^^^^^^^^^^^^^^^^^^^^^
  File "C:\Users\Sulaiman\AppData\Local\Programs\Python\Python311\Lib\site-packages\django\core\handlers\base.py", line 197, in _get_response
    response = wrapped_callback(request, *callback_args, **callback_kwargs)
               ^^^^^^^^^^^^^^^^^^^^^^^^^^^^^^^^^^^^^^^^^^^^^^^^^^^^^^^^^^^^
  File "C:\Users\Sulaiman\Desktop\New folder (2)\student-result\students\views.py", line 985, in student_Results
    semester = request.GET.get('semester') or (current_semester.semester if current_semester else 1)
                                                                            ^^^^^^^^^^^^^^^^
UnboundLocalError: cannot access local variable 'current_semester' where it is not associated with a value
"GET /student_results/688010001/ HTTP/1.1" 500 79951
Internal Server Error: /student_results/688010001/
Traceback (most recent call last):
  File "C:\Users\Sulaiman\AppData\Local\Programs\Python\Python311\Lib\site-packages\django\core\handlers\exception.py", line 55, in inner
    response = get_response(request)
               ^^^^^^^^^^^^^^^^^^^^^
  File "C:\Users\Sulaiman\AppData\Local\Programs\Python\Python311\Lib\site-packages\django\core\handlers\base.py", line 197, in _get_response
    response = wrapped_callback(request, *callback_args, **callback_kwargs)
               ^^^^^^^^^^^^^^^^^^^^^^^^^^^^^^^^^^^^^^^^^^^^^^^^^^^^^^^^^^^^
  File "C:\Users\Sulaiman\Desktop\New folder (2)\student-result\students\views.py", line 985, in student_Results
    semester = request.GET.get('semester') or (current_semester.semester if current_semester else 1)
                                                                            ^^^^^^^^^^^^^^^^
UnboundLocalError: cannot access local variable 'current_semester' where it is not associated with a value
"GET /student_results/688010001/ HTTP/1.1" 500 79645
Internal Server Error: /student_results/688010001/
Traceback (most recent call last):
  File "C:\Users\Sulaiman\AppData\Local\Programs\Python\Python311\Lib\site-packages\django\core\handlers\exception.py", line 55, in inner
    response = get_response(request)
               ^^^^^^^^^^^^^^^^^^^^^
  File "C:\Users\Sulaiman\AppData\Local\Programs\Python\Python311\Lib\site-packages\django\core\handlers\base.py", line 197, in _get_response
    response = wrapped_callback(request, *callback_args, **callback_kwargs)
               ^^^^^^^^^^^^^^^^^^^^^^^^^^^^^^^^^^^^^^^^^^^^^^^^^^^^^^^^^^^^
  File "C:\Users\Sulaiman\Desktop\New folder (2)\student-result\students\views.py", line 1193, in student_Results
    return download_result_pdf(
           ^^^^^^^^^^^^^^^^^^^^
TypeError: download_result_pdf() got an unexpected keyword argument 'semester_display'
"GET /student_results/688010001/?academic_year=2025&download_pdf= HTTP/1.1" 500 85546
Internal Server Error: /student_results/688010001/
Traceback (most recent call last):
  File "C:\Users\Sulaiman\AppData\Local\Programs\Python\Python311\Lib\site-packages\django\core\handlers\exception.py", line 55, in inner
    response = get_response(request)
               ^^^^^^^^^^^^^^^^^^^^^
  File "C:\Users\Sulaiman\AppData\Local\Programs\Python\Python311\Lib\site-packages\django\core\handlers\base.py", line 197, in _get_response
    response = wrapped_callback(request, *callback_args, **callback_kwargs)
               ^^^^^^^^^^^^^^^^^^^^^^^^^^^^^^^^^^^^^^^^^^^^^^^^^^^^^^^^^^^^
  File "C:\Users\Sulaiman\Desktop\New folder (2)\student-result\students\views.py", line 1193, in student_Results
    return download_result_pdf(
           ^^^^^^^^^^^^^^^^^^^^
  File "C:\Users\Sulaiman\Desktop\New folder (2)\student-result\students\views.py", line 1052, in download_result_pdf
    semester = request.GET.get('semester')
               ^^^^^^^
NameError: name 'request' is not defined
"GET /student_results/688010001/?academic_year=2025&download_pdf= HTTP/1.1" 500 91180
Internal Server Error: /student_results/688010001/
Traceback (most recent call last):
  File "C:\Users\Sulaiman\AppData\Local\Programs\Python\Python311\Lib\site-packages\django\core\handlers\exception.py", line 55, in inner
    response = get_response(request)
               ^^^^^^^^^^^^^^^^^^^^^
  File "C:\Users\Sulaiman\AppData\Local\Programs\Python\Python311\Lib\site-packages\django\core\handlers\base.py", line 197, in _get_response
    response = wrapped_callback(request, *callback_args, **callback_kwargs)
               ^^^^^^^^^^^^^^^^^^^^^^^^^^^^^^^^^^^^^^^^^^^^^^^^^^^^^^^^^^^^
  File "C:\Users\Sulaiman\Desktop\New folder (2)\student-result\students\views.py", line 1193, in student_Results
    return download_result_pdf(
           ^^^^^^^^^^^^^^^^^^^^
  File "C:\Users\Sulaiman\Desktop\New folder (2)\student-result\students\views.py", line 1052, in download_result_pdf
    semester = request.GET.get('semester')
               ^^^^^^^
NameError: name 'request' is not defined
"GET /student_results/688010001/?academic_year=2025&download_pdf= HTTP/1.1" 500 91180
Internal Server Error: /student_results/688010001/
Traceback (most recent call last):
  File "C:\Users\Sulaiman\AppData\Local\Programs\Python\Python311\Lib\site-packages\django\core\handlers\exception.py", line 55, in inner
    response = get_response(request)
               ^^^^^^^^^^^^^^^^^^^^^
  File "C:\Users\Sulaiman\AppData\Local\Programs\Python\Python311\Lib\site-packages\django\core\handlers\base.py", line 197, in _get_response
    response = wrapped_callback(request, *callback_args, **callback_kwargs)
               ^^^^^^^^^^^^^^^^^^^^^^^^^^^^^^^^^^^^^^^^^^^^^^^^^^^^^^^^^^^^
  File "C:\Users\Sulaiman\Desktop\New folder (2)\student-result\students\views.py", line 1193, in student_Results
    return download_result_pdf(
           ^^^^^^^^^^^^^^^^^^^^
TypeError: download_result_pdf() missing 1 required positional argument: 'semester_display'
"GET /student_results/688010001/?academic_year=2025&download_pdf= HTTP/1.1" 500 85703
Internal Server Error: /student_results/688010001/
Traceback (most recent call last):
  File "C:\Users\Sulaiman\AppData\Local\Programs\Python\Python311\Lib\site-packages\django\core\handlers\exception.py", line 55, in inner
    response = get_response(request)
               ^^^^^^^^^^^^^^^^^^^^^
  File "C:\Users\Sulaiman\AppData\Local\Programs\Python\Python311\Lib\site-packages\django\core\handlers\base.py", line 197, in _get_response
    response = wrapped_callback(request, *callback_args, **callback_kwargs)
               ^^^^^^^^^^^^^^^^^^^^^^^^^^^^^^^^^^^^^^^^^^^^^^^^^^^^^^^^^^^^
  File "C:\Users\Sulaiman\Desktop\New folder (2)\student-result\students\views.py", line 1193, in student_Results
    return download_result_pdf(
           ^^^^^^^^^^^^^^^^^^^^
TypeError: download_result_pdf() missing 1 required positional argument: 'semester_display'
"GET /student_results/688010001/?academic_year=2025&download_pdf= HTTP/1.1" 500 85356
Internal Server Error: /student_results/688010001/
Traceback (most recent call last):
  File "C:\Users\Sulaiman\AppData\Local\Programs\Python\Python311\Lib\site-packages\django\core\handlers\exception.py", line 55, in inner
    response = get_response(request)
               ^^^^^^^^^^^^^^^^^^^^^
  File "C:\Users\Sulaiman\AppData\Local\Programs\Python\Python311\Lib\site-packages\django\core\handlers\base.py", line 197, in _get_response
    response = wrapped_callback(request, *callback_args, **callback_kwargs)
               ^^^^^^^^^^^^^^^^^^^^^^^^^^^^^^^^^^^^^^^^^^^^^^^^^^^^^^^^^^^^
  File "C:\Users\Sulaiman\Desktop\New folder (2)\student-result\students\views.py", line 1186, in student_Results
    return download_result_pdf(
           ^^^^^^^^^^^^^^^^^^^^
TypeError: download_result_pdf() missing 1 required positional argument: 'subject_totals'
"GET /student_results/688010001/?academic_year=2025&download_pdf= HTTP/1.1" 500 85766
"GET /student_results/688010001/?academic_year=2025&download_pdf= HTTP/1.1" 500 85918
"GET /student_results/688010001/?academic_year=2025&download_pdf= HTTP/1.1" 500 85918
"GET /student_results/688010001/?academic_year=2025&download_pdf= HTTP/1.1" 500 85952
"GET /student_results/688010001/?academic_year=2025&download_pdf= HTTP/1.1" 500 107477
"GET /student_results/688010001/?academic_year=2025&download_pdf= HTTP/1.1" 500 85816
"GET /student_results/688010001/?academic_year=2025&download_pdf= HTTP/1.1" 500 85935
"GET /student_results/688010001/?academic_year=2025&download_pdf= HTTP/1.1" 500 85935
"GET /student_results/688010001/?academic_year=2025&download_pdf= HTTP/1.1" 500 85587
Internal Server Error: /student_results/688010001/
Traceback (most recent call last):
  File "C:\Users\Sulaiman\AppData\Local\Programs\Python\Python311\Lib\site-packages\django\core\handlers\exception.py", line 55, in inner
    response = get_response(request)
               ^^^^^^^^^^^^^^^^^^^^^
  File "C:\Users\Sulaiman\AppData\Local\Programs\Python\Python311\Lib\site-packages\django\core\handlers\base.py", line 197, in _get_response
    response = wrapped_callback(request, *callback_args, **callback_kwargs)
               ^^^^^^^^^^^^^^^^^^^^^^^^^^^^^^^^^^^^^^^^^^^^^^^^^^^^^^^^^^^^
  File "C:\Users\Sulaiman\Desktop\New folder (2)\student-result\students\views.py", line 1195, in student_Results
    )
      
UnboundLocalError: cannot access local variable 'subject_totals' where it is not associated with a value
"GET /student_results/688010001/?academic_year=2025&download_pdf= HTTP/1.1" 500 85676
Internal Server Error: /student_results/688010001/
Traceback (most recent call last):
  File "C:\Users\Sulaiman\AppData\Local\Programs\Python\Python311\Lib\site-packages\django\core\handlers\exception.py", line 55, in inner
    response = get_response(request)
               ^^^^^^^^^^^^^^^^^^^^^
  File "C:\Users\Sulaiman\AppData\Local\Programs\Python\Python311\Lib\site-packages\django\core\handlers\base.py", line 197, in _get_response
    response = wrapped_callback(request, *callback_args, **callback_kwargs)
               ^^^^^^^^^^^^^^^^^^^^^^^^^^^^^^^^^^^^^^^^^^^^^^^^^^^^^^^^^^^^
  File "C:\Users\Sulaiman\Desktop\New folder (2)\student-result\students\views.py", line 1182, in student_Results
    return download_result_pdf(
           ^^^^^^^^^^^^^^^^^^^^
TypeError: download_result_pdf() missing 1 required positional argument: 'subject_totals'
"GET /student_results/688010001/?academic_year=2025&download_pdf= HTTP/1.1" 500 85904
Internal Server Error: /student_results/688010001/
Traceback (most recent call last):
  File "C:\Users\Sulaiman\AppData\Local\Programs\Python\Python311\Lib\site-packages\django\core\handlers\exception.py", line 55, in inner
    response = get_response(request)
               ^^^^^^^^^^^^^^^^^^^^^
  File "C:\Users\Sulaiman\AppData\Local\Programs\Python\Python311\Lib\site-packages\django\core\handlers\base.py", line 197, in _get_response
    response = wrapped_callback(request, *callback_args, **callback_kwargs)
               ^^^^^^^^^^^^^^^^^^^^^^^^^^^^^^^^^^^^^^^^^^^^^^^^^^^^^^^^^^^^
  File "C:\Users\Sulaiman\Desktop\New folder (2)\student-result\students\views.py", line 1176, in student_Results
    subjects_cat1_data = get_subject_data(student, selected_academic_year, category=1, semester="1")
                         ^^^^^^^^^^^^^^^^
NameError: name 'get_subject_data' is not defined
"GET /student_results/688010001/?academic_year=2025&semester=2 HTTP/1.1" 500 83210
Internal Server Error: /student_results/688010001/
Traceback (most recent call last):
  File "C:\Users\Sulaiman\AppData\Local\Programs\Python\Python311\Lib\site-packages\django\core\handlers\exception.py", line 55, in inner
    response = get_response(request)
               ^^^^^^^^^^^^^^^^^^^^^
  File "C:\Users\Sulaiman\AppData\Local\Programs\Python\Python311\Lib\site-packages\django\core\handlers\base.py", line 197, in _get_response
    response = wrapped_callback(request, *callback_args, **callback_kwargs)
               ^^^^^^^^^^^^^^^^^^^^^^^^^^^^^^^^^^^^^^^^^^^^^^^^^^^^^^^^^^^^
  File "C:\Users\Sulaiman\Desktop\New folder (2)\student-result\students\views.py", line 1176, in student_Results
    subjects_cat1_data = get_subject_data(student, selected_academic_year, category=1, semester="1")
                         ^^^^^^^^^^^^^^^^
NameError: name 'get_subject_data' is not defined
"GET /student_results/688010001/?academic_year=2025&semester=2 HTTP/1.1" 500 83210
Internal Server Error: /student_results/688010001/
Traceback (most recent call last):
  File "C:\Users\Sulaiman\AppData\Local\Programs\Python\Python311\Lib\site-packages\django\core\handlers\exception.py", line 55, in inner
    response = get_response(request)
               ^^^^^^^^^^^^^^^^^^^^^
  File "C:\Users\Sulaiman\AppData\Local\Programs\Python\Python311\Lib\site-packages\django\core\handlers\base.py", line 197, in _get_response
    response = wrapped_callback(request, *callback_args, **callback_kwargs)
               ^^^^^^^^^^^^^^^^^^^^^^^^^^^^^^^^^^^^^^^^^^^^^^^^^^^^^^^^^^^^
  File "C:\Users\Sulaiman\Desktop\New folder (2)\student-result\students\views.py", line 1162, in student_Results
    history_records_1 = StudentHistory.objects.filter(
                        ^^^^^^^^^^^^^^^^^^^^^^^^^^^^^^
  File "C:\Users\Sulaiman\AppData\Local\Programs\Python\Python311\Lib\site-packages\django\db\models\manager.py", line 87, in manager_method
    return getattr(self.get_queryset(), name)(*args, **kwargs)
           ^^^^^^^^^^^^^^^^^^^^^^^^^^^^^^^^^^^^^^^^^^^^^^^^^^^
  File "C:\Users\Sulaiman\AppData\Local\Programs\Python\Python311\Lib\site-packages\django\db\models\query.py", line 1476, in filter
    return self._filter_or_exclude(False, args, kwargs)
           ^^^^^^^^^^^^^^^^^^^^^^^^^^^^^^^^^^^^^^^^^^^^
  File "C:\Users\Sulaiman\AppData\Local\Programs\Python\Python311\Lib\site-packages\django\db\models\query.py", line 1494, in _filter_or_exclude
    clone._filter_or_exclude_inplace(negate, args, kwargs)
  File "C:\Users\Sulaiman\AppData\Local\Programs\Python\Python311\Lib\site-packages\django\db\models\query.py", line 1501, in _filter_or_exclude_inplace
    self._query.add_q(Q(*args, **kwargs))
  File "C:\Users\Sulaiman\AppData\Local\Programs\Python\Python311\Lib\site-packages\django\db\models\sql\query.py", line 1609, in add_q
    clause, _ = self._add_q(q_object, self.used_aliases)
                ^^^^^^^^^^^^^^^^^^^^^^^^^^^^^^^^^^^^^^^^
  File "C:\Users\Sulaiman\AppData\Local\Programs\Python\Python311\Lib\site-packages\django\db\models\sql\query.py", line 1641, in _add_q
    child_clause, needed_inner = self.build_filter(
                                 ^^^^^^^^^^^^^^^^^^
  File "C:\Users\Sulaiman\AppData\Local\Programs\Python\Python311\Lib\site-packages\django\db\models\sql\query.py", line 1491, in build_filter
    lookups, parts, reffed_expression = self.solve_lookup_type(arg, summarize)
                                        ^^^^^^^^^^^^^^^^^^^^^^^^^^^^^^^^^^^^^^
  File "C:\Users\Sulaiman\AppData\Local\Programs\Python\Python311\Lib\site-packages\django\db\models\sql\query.py", line 1303, in solve_lookup_type
    _, field, _, lookup_parts = self.names_to_path(lookup_splitted, self.get_meta())
                                ^^^^^^^^^^^^^^^^^^^^^^^^^^^^^^^^^^^^^^^^^^^^^^^^^^^^
  File "C:\Users\Sulaiman\AppData\Local\Programs\Python\Python311\Lib\site-packages\django\db\models\sql\query.py", line 1768, in names_to_path
    raise FieldError(
django.core.exceptions.FieldError: Cannot resolve keyword 'student' into field. Choices are: academic_year, grade_percentage, id, level_name, obtained_marks, pass_or_fail, school_name, semester, student_id, student_name, subject_marks, total_marks
"GET /student_results/688010001/?academic_year=2025&semester=2 HTTP/1.1" 500 128514
Internal Server Error: /student_results/688010001/
Traceback (most recent call last):
  File "C:\Users\Sulaiman\AppData\Local\Programs\Python\Python311\Lib\site-packages\django\core\handlers\exception.py", line 55, in inner
    response = get_response(request)
               ^^^^^^^^^^^^^^^^^^^^^
  File "C:\Users\Sulaiman\AppData\Local\Programs\Python\Python311\Lib\site-packages\django\core\handlers\base.py", line 197, in _get_response
    response = wrapped_callback(request, *callback_args, **callback_kwargs)
               ^^^^^^^^^^^^^^^^^^^^^^^^^^^^^^^^^^^^^^^^^^^^^^^^^^^^^^^^^^^^
  File "C:\Users\Sulaiman\Desktop\New folder (2)\student-result\students\views.py", line 1207, in student_Results
    school_name=student.school_name,
                ^^^^^^^^^^^^^^^^^^^
AttributeError: 'Student' object has no attribute 'school_name'
"GET /student_results/688010001/?academic_year=2025&download_pdf= HTTP/1.1" 500 84863
Internal Server Error: /student_results/688010001/
Traceback (most recent call last):
  File "C:\Users\Sulaiman\AppData\Local\Programs\Python\Python311\Lib\site-packages\django\core\handlers\exception.py", line 55, in inner
    response = get_response(request)
               ^^^^^^^^^^^^^^^^^^^^^
  File "C:\Users\Sulaiman\AppData\Local\Programs\Python\Python311\Lib\site-packages\django\core\handlers\base.py", line 197, in _get_response
    response = wrapped_callback(request, *callback_args, **callback_kwargs)
               ^^^^^^^^^^^^^^^^^^^^^^^^^^^^^^^^^^^^^^^^^^^^^^^^^^^^^^^^^^^^
  File "C:\Users\Sulaiman\Desktop\New folder (2)\student-result\students\views.py", line 1193, in student_Results
    return download_result_pdf(
           ^^^^^^^^^^^^^^^^^^^^
TypeError: download_result_pdf() got an unexpected keyword argument 'semester_display'
"GET /student_results/688010001/?academic_year=2025&download_pdf= HTTP/1.1" 500 85547
"GET /student_results/688010001/?academic_year=2025&semester=1&download_pdf= HTTP/1.1" 500 210331
"GET /student_results/688010001/?academic_year=2025&semester=1&download_pdf= HTTP/1.1" 500 99180
"GET /student_results/688010001/?academic_year=2025&semester=1&download_pdf= HTTP/1.1" 500 99445
"GET /student_results/688010001/?academic_year=2025&semester=1&download_pdf= HTTP/1.1" 500 99317
"GET /student_results/688010001/?academic_year=2025&semester=1&download_pdf= HTTP/1.1" 500 99317
"GET /student_results/688010001/?academic_year=2025&semester=1&download_pdf= HTTP/1.1" 500 99317
"GET /student_results/688010001/?academic_year=2025&semester=1&download_pdf= HTTP/1.1" 500 99317
Internal Server Error: /student_results/688010001/
Traceback (most recent call last):
  File "C:\Users\Sulaiman\AppData\Local\Programs\Python\Python311\Lib\site-packages\django\core\handlers\exception.py", line 55, in inner
    response = get_response(request)
               ^^^^^^^^^^^^^^^^^^^^^
  File "C:\Users\Sulaiman\AppData\Local\Programs\Python\Python311\Lib\site-packages\django\core\handlers\base.py", line 197, in _get_response
    response = wrapped_callback(request, *callback_args, **callback_kwargs)
               ^^^^^^^^^^^^^^^^^^^^^^^^^^^^^^^^^^^^^^^^^^^^^^^^^^^^^^^^^^^^
  File "C:\Users\Sulaiman\Desktop\New folder (2)\student-result\students\views.py", line 1020, in student_Results
    return download_result_pdfs(
           ^^^^^^^^^^^^^^^^^^^^^
TypeError: download_result_pdfs() got an unexpected keyword argument 'students'
"GET /student_results/688010001/?academic_year=2025&semester=1&download_pdf= HTTP/1.1" 500 89233
Internal Server Error: /student_results/688010001/
Traceback (most recent call last):
  File "C:\Users\Sulaiman\AppData\Local\Programs\Python\Python311\Lib\site-packages\django\core\handlers\exception.py", line 55, in inner
    response = get_response(request)
               ^^^^^^^^^^^^^^^^^^^^^
  File "C:\Users\Sulaiman\AppData\Local\Programs\Python\Python311\Lib\site-packages\django\core\handlers\base.py", line 197, in _get_response
    response = wrapped_callback(request, *callback_args, **callback_kwargs)
               ^^^^^^^^^^^^^^^^^^^^^^^^^^^^^^^^^^^^^^^^^^^^^^^^^^^^^^^^^^^^
  File "C:\Users\Sulaiman\Desktop\New folder (2)\student-result\students\views.py", line 1020, in student_Results
    return download_result_pdfs(
           ^^^^^^^^^^^^^^^^^^^^^
TypeError: download_result_pdfs() got an unexpected keyword argument 'students'
"GET /student_results/688010001/?academic_year=2025&semester=&download_pdf= HTTP/1.1" 500 91101
Internal Server Error: /student_results/688010001/
Traceback (most recent call last):
  File "C:\Users\Sulaiman\AppData\Local\Programs\Python\Python311\Lib\site-packages\django\core\handlers\exception.py", line 55, in inner
    response = get_response(request)
               ^^^^^^^^^^^^^^^^^^^^^
  File "C:\Users\Sulaiman\AppData\Local\Programs\Python\Python311\Lib\site-packages\django\core\handlers\base.py", line 197, in _get_response
    response = wrapped_callback(request, *callback_args, **callback_kwargs)
               ^^^^^^^^^^^^^^^^^^^^^^^^^^^^^^^^^^^^^^^^^^^^^^^^^^^^^^^^^^^^
  File "C:\Users\Sulaiman\Desktop\New folder (2)\student-result\students\views.py", line 1020, in student_Results
    return download_result_pdf(
           ^^^^^^^^^^^^^^^^^^^
NameError: name 'download_result_pdf' is not defined
"GET /student_results/688010001/?academic_year=2025&semester=&download_pdf= HTTP/1.1" 500 91166
Internal Server Error: /student_results/688010001/
Traceback (most recent call last):
  File "C:\Users\Sulaiman\AppData\Local\Programs\Python\Python311\Lib\site-packages\django\core\handlers\exception.py", line 55, in inner
    response = get_response(request)
               ^^^^^^^^^^^^^^^^^^^^^
  File "C:\Users\Sulaiman\AppData\Local\Programs\Python\Python311\Lib\site-packages\django\core\handlers\base.py", line 197, in _get_response
    response = wrapped_callback(request, *callback_args, **callback_kwargs)
               ^^^^^^^^^^^^^^^^^^^^^^^^^^^^^^^^^^^^^^^^^^^^^^^^^^^^^^^^^^^^
  File "C:\Users\Sulaiman\Desktop\New folder (2)\student-result\students\views.py", line 1020, in student_Results
    return download_result_pdf(
           ^^^^^^^^^^^^^^^^^^^
NameError: name 'download_result_pdf' is not defined
"GET /student_results/688010001/?academic_year=2025&semester=&download_pdf= HTTP/1.1" 500 91166
Internal Server Error: /student_results/688010001/
Traceback (most recent call last):
  File "C:\Users\Sulaiman\AppData\Local\Programs\Python\Python311\Lib\site-packages\django\core\handlers\exception.py", line 55, in inner
    response = get_response(request)
               ^^^^^^^^^^^^^^^^^^^^^
  File "C:\Users\Sulaiman\AppData\Local\Programs\Python\Python311\Lib\site-packages\django\core\handlers\base.py", line 197, in _get_response
    response = wrapped_callback(request, *callback_args, **callback_kwargs)
               ^^^^^^^^^^^^^^^^^^^^^^^^^^^^^^^^^^^^^^^^^^^^^^^^^^^^^^^^^^^^
  File "C:\Users\Sulaiman\Desktop\New folder (2)\student-result\students\views.py", line 1020, in student_Results
    return download_result_pdfs(
           ^^^^^^^^^^^^^^^^^^^^^
TypeError: download_result_pdfs() got an unexpected keyword argument 'students'
"GET /student_results/688010001/?academic_year=2025&semester=&download_pdf= HTTP/1.1" 500 91238
Internal Server Error: /student_results/688010001/
Traceback (most recent call last):
  File "C:\Users\Sulaiman\AppData\Local\Programs\Python\Python311\Lib\site-packages\django\core\handlers\exception.py", line 55, in inner
    response = get_response(request)
               ^^^^^^^^^^^^^^^^^^^^^
  File "C:\Users\Sulaiman\AppData\Local\Programs\Python\Python311\Lib\site-packages\django\core\handlers\base.py", line 197, in _get_response
    response = wrapped_callback(request, *callback_args, **callback_kwargs)
               ^^^^^^^^^^^^^^^^^^^^^^^^^^^^^^^^^^^^^^^^^^^^^^^^^^^^^^^^^^^^
  File "C:\Users\Sulaiman\Desktop\New folder (2)\student-result\students\views.py", line 1020, in student_Results
    return download_result_pdfs(
           ^^^^^^^^^^^^^^^^^^^^^
TypeError: download_result_pdfs() got an unexpected keyword argument 'students'
"GET /student_results/688010001/?academic_year=2025&semester=&download_pdf= HTTP/1.1" 500 91101
Internal Server Error: /ingr_student
Traceback (most recent call last):
  File "C:\Users\Sulaiman\AppData\Local\Programs\Python\Python311\Lib\site-packages\django\core\handlers\exception.py", line 55, in inner
    response = get_response(request)
               ^^^^^^^^^^^^^^^^^^^^^
  File "C:\Users\Sulaiman\AppData\Local\Programs\Python\Python311\Lib\site-packages\django\core\handlers\base.py", line 197, in _get_response
    response = wrapped_callback(request, *callback_args, **callback_kwargs)
               ^^^^^^^^^^^^^^^^^^^^^^^^^^^^^^^^^^^^^^^^^^^^^^^^^^^^^^^^^^^^
  File "C:\Users\Sulaiman\Desktop\New folder (2)\student-result\students\views.py", line 657, in student_marks_view
    subjects = SubjectToStudy.objects.filter(
               ^^^^^^^^^^^^^^^^^^^^^^^^^^^^^^
  File "C:\Users\Sulaiman\AppData\Local\Programs\Python\Python311\Lib\site-packages\django\db\models\manager.py", line 87, in manager_method
    return getattr(self.get_queryset(), name)(*args, **kwargs)
           ^^^^^^^^^^^^^^^^^^^^^^^^^^^^^^^^^^^^^^^^^^^^^^^^^^^
  File "C:\Users\Sulaiman\AppData\Local\Programs\Python\Python311\Lib\site-packages\django\db\models\query.py", line 1476, in filter
    return self._filter_or_exclude(False, args, kwargs)
           ^^^^^^^^^^^^^^^^^^^^^^^^^^^^^^^^^^^^^^^^^^^^
  File "C:\Users\Sulaiman\AppData\Local\Programs\Python\Python311\Lib\site-packages\django\db\models\query.py", line 1494, in _filter_or_exclude
    clone._filter_or_exclude_inplace(negate, args, kwargs)
  File "C:\Users\Sulaiman\AppData\Local\Programs\Python\Python311\Lib\site-packages\django\db\models\query.py", line 1501, in _filter_or_exclude_inplace
    self._query.add_q(Q(*args, **kwargs))
  File "C:\Users\Sulaiman\AppData\Local\Programs\Python\Python311\Lib\site-packages\django\db\models\sql\query.py", line 1609, in add_q
    clause, _ = self._add_q(q_object, self.used_aliases)
                ^^^^^^^^^^^^^^^^^^^^^^^^^^^^^^^^^^^^^^^^
  File "C:\Users\Sulaiman\AppData\Local\Programs\Python\Python311\Lib\site-packages\django\db\models\sql\query.py", line 1641, in _add_q
    child_clause, needed_inner = self.build_filter(
                                 ^^^^^^^^^^^^^^^^^^
  File "C:\Users\Sulaiman\AppData\Local\Programs\Python\Python311\Lib\site-packages\django\db\models\sql\query.py", line 1491, in build_filter
    lookups, parts, reffed_expression = self.solve_lookup_type(arg, summarize)
                                        ^^^^^^^^^^^^^^^^^^^^^^^^^^^^^^^^^^^^^^
  File "C:\Users\Sulaiman\AppData\Local\Programs\Python\Python311\Lib\site-packages\django\db\models\sql\query.py", line 1303, in solve_lookup_type
    _, field, _, lookup_parts = self.names_to_path(lookup_splitted, self.get_meta())
                                ^^^^^^^^^^^^^^^^^^^^^^^^^^^^^^^^^^^^^^^^^^^^^^^^^^^^
  File "C:\Users\Sulaiman\AppData\Local\Programs\Python\Python311\Lib\site-packages\django\db\models\sql\query.py", line 1768, in names_to_path
    raise FieldError(
django.core.exceptions.FieldError: Cannot resolve keyword 'category' into field. Choices are: id, level, level_id, semester, studentmarkforsubject, subject, subject_id
"GET /ingr_student?school=%E0%B8%AD%E0%B8%B4%E0%B8%AA%E0%B8%A5%E0%B8%B2%E0%B8%A1%E0%B8%B5%E0%B8%A2%E0%B8%B0%E0%B8%AE%E0%B9%8C&level=%E0%B8%A3%E0%B8%B0%E0%B8%94%E0%B8%B1%E0%B8%9A%E0%B8%8A%E0%B8%B1%E0%B9%89%E0%B8%99%E0%B8%9B%E0%B8%B5+1&academic_year=2568&category=1 HTTP/1.1" 500 134046
Internal Server Error: /gr_student
Traceback (most recent call last):
  File "C:\Users\Sulaiman\AppData\Local\Programs\Python\Python311\Lib\site-packages\django\core\handlers\exception.py", line 55, in inner
    response = get_response(request)
               ^^^^^^^^^^^^^^^^^^^^^
  File "C:\Users\Sulaiman\AppData\Local\Programs\Python\Python311\Lib\site-packages\django\core\handlers\base.py", line 197, in _get_response
    response = wrapped_callback(request, *callback_args, **callback_kwargs)
               ^^^^^^^^^^^^^^^^^^^^^^^^^^^^^^^^^^^^^^^^^^^^^^^^^^^^^^^^^^^^
  File "C:\Users\Sulaiman\Desktop\New folder (2)\student-result\students\views.py", line 786, in GR_Student
    default_semester = current_semester.semester
                       ^^^^^^^^^^^^^^^^^^^^^^^^^
AttributeError: 'CurrentSemester' object has no attribute 'semester'
"GET /gr_student HTTP/1.1" 500 80636
Internal Server Error: /download_student_results_pdf/
Traceback (most recent call last):
  File "C:\Users\Sulaiman\AppData\Local\Programs\Python\Python311\Lib\site-packages\django\core\handlers\exception.py", line 55, in inner
    response = get_response(request)
               ^^^^^^^^^^^^^^^^^^^^^
  File "C:\Users\Sulaiman\AppData\Local\Programs\Python\Python311\Lib\site-packages\django\core\handlers\base.py", line 197, in _get_response
    response = wrapped_callback(request, *callback_args, **callback_kwargs)
               ^^^^^^^^^^^^^^^^^^^^^^^^^^^^^^^^^^^^^^^^^^^^^^^^^^^^^^^^^^^^
  File "C:\Users\Sulaiman\Desktop\New folder (2)\student-result\students\views.py", line 933, in download_student_results_pdf
    logo_path = os.path.join('static', 'images', 'logo.ico')
                ^^
NameError: name 'os' is not defined
"GET /download_student_results_pdf/?school=%E0%B8%AD%E0%B8%B4%E0%B8%AA%E0%B8%A5%E0%B8%B2%E0%B8%A1%E0%B8%B5%E0%B8%A2%E0%B8%B0%E0%B8%AE%E0%B9%8C&level=%E0%B8%A3%E0%B8%B0%E0%B8%94%E0%B8%B1%E0%B8%9A%E0%B8%8A%E0%B8%B1%E0%B9%89%E0%B8%99%E0%B8%9B%E0%B8%B5+1&academic_year=2568&semester= HTTP/1.1" 500 87076
Internal Server Error: /download_student_results_pdf/
Traceback (most recent call last):
  File "C:\Users\Sulaiman\AppData\Local\Programs\Python\Python311\Lib\site-packages\django\core\handlers\exception.py", line 55, in inner
    response = get_response(request)
               ^^^^^^^^^^^^^^^^^^^^^
  File "C:\Users\Sulaiman\AppData\Local\Programs\Python\Python311\Lib\site-packages\django\core\handlers\base.py", line 197, in _get_response
    response = wrapped_callback(request, *callback_args, **callback_kwargs)
               ^^^^^^^^^^^^^^^^^^^^^^^^^^^^^^^^^^^^^^^^^^^^^^^^^^^^^^^^^^^^
  File "C:\Users\Sulaiman\Desktop\New folder (2)\student-result\students\views.py", line 900, in download_student_results_pdf
    filename = f"results_{academic_year_thai - 543 or 'all'}_{category_display}.pdf"
                          ~~~~~~~~~~~~~~~~~~~^~~~~
TypeError: unsupported operand type(s) for -: 'str' and 'int'
"GET /download_student_results_pdf/?school=%E0%B8%AD%E0%B8%B4%E0%B8%AA%E0%B8%A5%E0%B8%B2%E0%B8%A1%E0%B8%B5%E0%B8%A2%E0%B8%B0%E0%B8%AE%E0%B9%8C&level=%E0%B8%A3%E0%B8%B0%E0%B8%94%E0%B8%B1%E0%B8%9A%E0%B8%8A%E0%B8%B1%E0%B9%89%E0%B8%99%E0%B8%9B%E0%B8%B5+1&academic_year=2568&category=1 HTTP/1.1" 500 84274
Internal Server Error: /download_student_results_pdf/
Traceback (most recent call last):
  File "C:\Users\Sulaiman\AppData\Local\Programs\Python\Python311\Lib\site-packages\django\core\handlers\exception.py", line 55, in inner
    response = get_response(request)
               ^^^^^^^^^^^^^^^^^^^^^
  File "C:\Users\Sulaiman\AppData\Local\Programs\Python\Python311\Lib\site-packages\django\core\handlers\base.py", line 197, in _get_response
    response = wrapped_callback(request, *callback_args, **callback_kwargs)
               ^^^^^^^^^^^^^^^^^^^^^^^^^^^^^^^^^^^^^^^^^^^^^^^^^^^^^^^^^^^^
  File "C:\Users\Sulaiman\Desktop\New folder (2)\student-result\students\views.py", line 900, in download_student_results_pdf
    filename = f"results_{academic_year_thai - 543 or 'all'}_{category_display}.pdf"
                          ~~~~~~~~~~~~~~~~~~~^~~~~
TypeError: unsupported operand type(s) for -: 'str' and 'int'
"GET /download_student_results_pdf/?school=%E0%B8%AD%E0%B8%B4%E0%B8%AA%E0%B8%A5%E0%B8%B2%E0%B8%A1%E0%B8%B5%E0%B8%A2%E0%B8%B0%E0%B8%AE%E0%B9%8C&level=%E0%B8%A3%E0%B8%B0%E0%B8%94%E0%B8%B1%E0%B8%9A%E0%B8%8A%E0%B8%B1%E0%B9%89%E0%B8%99%E0%B8%9B%E0%B8%B5+1&academic_year=2025&category=1 HTTP/1.1" 500 86476
Internal Server Error: /download_student_results_pdf/
Traceback (most recent call last):
  File "C:\Users\Sulaiman\AppData\Local\Programs\Python\Python311\Lib\site-packages\django\core\handlers\exception.py", line 55, in inner
    response = get_response(request)
               ^^^^^^^^^^^^^^^^^^^^^
  File "C:\Users\Sulaiman\AppData\Local\Programs\Python\Python311\Lib\site-packages\django\core\handlers\base.py", line 197, in _get_response
    response = wrapped_callback(request, *callback_args, **callback_kwargs)
               ^^^^^^^^^^^^^^^^^^^^^^^^^^^^^^^^^^^^^^^^^^^^^^^^^^^^^^^^^^^^
  File "C:\Users\Sulaiman\Desktop\New folder (2)\student-result\students\views.py", line 900, in download_student_results_pdf
    filename = f"results_{academic_year_thai  or 'all'}_{category_display}.pdf"
                          ^^^^^^^^^^^^^^^^^^^^^^^^
TypeError: unsupported operand type(s) for -: 'str' and 'int'
"GET /download_student_results_pdf/?school=%E0%B8%AD%E0%B8%B4%E0%B8%AA%E0%B8%A5%E0%B8%B2%E0%B8%A1%E0%B8%B5%E0%B8%A2%E0%B8%B0%E0%B8%AE%E0%B9%8C&level=%E0%B8%A3%E0%B8%B0%E0%B8%94%E0%B8%B1%E0%B8%9A%E0%B8%8A%E0%B8%B1%E0%B9%89%E0%B8%99%E0%B8%9B%E0%B8%B5+1&academic_year=2025&category=1 HTTP/1.1" 500 86603
Internal Server Error: /gr_student
Traceback (most recent call last):
  File "C:\Users\Sulaiman\AppData\Local\Programs\Python\Python311\Lib\site-packages\django\core\handlers\exception.py", line 55, in inner
    response = get_response(request)
               ^^^^^^^^^^^^^^^^^^^^^
  File "C:\Users\Sulaiman\AppData\Local\Programs\Python\Python311\Lib\site-packages\django\core\handlers\base.py", line 197, in _get_response
    response = wrapped_callback(request, *callback_args, **callback_kwargs)
               ^^^^^^^^^^^^^^^^^^^^^^^^^^^^^^^^^^^^^^^^^^^^^^^^^^^^^^^^^^^^
  File "C:\Users\Sulaiman\Desktop\New folder (2)\student-result\students\views.py", line 790, in GR_Student
    academic_year_thai = convert_year_to_thai(academic_year)
                         ^^^^^^^^^^^^^^^^^^^^
NameError: name 'convert_year_to_thai' is not defined
"GET /gr_student?school=%E0%B8%AD%E0%B8%B4%E0%B8%AA%E0%B8%A5%E0%B8%B2%E0%B8%A1%E0%B8%B5%E0%B8%A2%E0%B8%B0%E0%B8%AE%E0%B9%8C&level=%E0%B8%A3%E0%B8%B0%E0%B8%94%E0%B8%B1%E0%B8%9A%E0%B8%8A%E0%B8%B1%E0%B9%89%E0%B8%99%E0%B8%9B%E0%B8%B5+1&academic_year=2025&category=2 HTTP/1.1" 500 83797
Internal Server Error: /student_results/688010001/
Traceback (most recent call last):
  File "C:\Users\Sulaiman\AppData\Local\Programs\Python\Python311\Lib\site-packages\django\core\handlers\exception.py", line 55, in inner
    response = get_response(request)
               ^^^^^^^^^^^^^^^^^^^^^
  File "C:\Users\Sulaiman\AppData\Local\Programs\Python\Python311\Lib\site-packages\django\core\handlers\base.py", line 197, in _get_response
    response = wrapped_callback(request, *callback_args, **callback_kwargs)
               ^^^^^^^^^^^^^^^^^^^^^^^^^^^^^^^^^^^^^^^^^^^^^^^^^^^^^^^^^^^^
  File "C:\Users\Sulaiman\Desktop\New folder (2)\student-result\students\views.py", line 983, in student_Results
    academic_year=convert_year_to_thai(selected_academic_year),
                  ^^^^^^^^^^^^^^^^^^^^
NameError: name 'convert_year_to_thai' is not defined
"GET /student_results/688010001/?academic_year=2025&semester=&download_pdf= HTTP/1.1" 500 84520
Internal Server Error: /student_results/688010001/
Traceback (most recent call last):
  File "C:\Users\Sulaiman\AppData\Local\Programs\Python\Python311\Lib\site-packages\django\core\handlers\exception.py", line 55, in inner
    response = get_response(request)
               ^^^^^^^^^^^^^^^^^^^^^
  File "C:\Users\Sulaiman\AppData\Local\Programs\Python\Python311\Lib\site-packages\django\core\handlers\base.py", line 197, in _get_response
    response = wrapped_callback(request, *callback_args, **callback_kwargs)
               ^^^^^^^^^^^^^^^^^^^^^^^^^^^^^^^^^^^^^^^^^^^^^^^^^^^^^^^^^^^^
  File "C:\Users\Sulaiman\Desktop\New folder (2)\student-result\students\views.py", line 985, in student_Results
    academic_year=convert_year_to_thai(str(selected_academic_year)),
                  ^^^^^^^^^^^^^^^^^^^^
NameError: name 'convert_year_to_thai' is not defined
"GET /student_results/688010001/?academic_year=2025&category=&download_pdf= HTTP/1.1" 500 84571
Internal Server Error: /ingr_student
Traceback (most recent call last):
  File "C:\Users\Sulaiman\AppData\Local\Programs\Python\Python311\Lib\site-packages\django\core\handlers\exception.py", line 55, in inner
    response = get_response(request)
               ^^^^^^^^^^^^^^^^^^^^^
  File "C:\Users\Sulaiman\AppData\Local\Programs\Python\Python311\Lib\site-packages\django\core\handlers\base.py", line 197, in _get_response
    response = wrapped_callback(request, *callback_args, **callback_kwargs)
               ^^^^^^^^^^^^^^^^^^^^^^^^^^^^^^^^^^^^^^^^^^^^^^^^^^^^^^^^^^^^
  File "C:\Users\Sulaiman\Desktop\New folder (2)\student-result\students\views.py", line 630, in student_marks_view
    years = [convert_year_to_thai(str(y)) for y in range(current_year, current_year - 10, -1)]
            ^^^^^^^^^^^^^^^^^^^^^^^^^^^^^^^^^^^^^^^^^^^^^^^^^^^^^^^^^^^^^^^^^^^^^^^^^^^^^^^^^^
  File "C:\Users\Sulaiman\Desktop\New folder (2)\student-result\students\views.py", line 630, in <listcomp>
    years = [convert_year_to_thai(str(y)) for y in range(current_year, current_year - 10, -1)]
             ^^^^^^^^^^^^^^^^^^^^
NameError: name 'convert_year_to_thai' is not defined
"GET /ingr_student HTTP/1.1" 500 84007
Internal Server Error: /ingr_student
Traceback (most recent call last):
  File "C:\Users\Sulaiman\AppData\Local\Programs\Python\Python311\Lib\site-packages\django\core\handlers\exception.py", line 55, in inner
    response = get_response(request)
               ^^^^^^^^^^^^^^^^^^^^^
  File "C:\Users\Sulaiman\AppData\Local\Programs\Python\Python311\Lib\site-packages\django\core\handlers\base.py", line 197, in _get_response
    response = wrapped_callback(request, *callback_args, **callback_kwargs)
               ^^^^^^^^^^^^^^^^^^^^^^^^^^^^^^^^^^^^^^^^^^^^^^^^^^^^^^^^^^^^
  File "C:\Users\Sulaiman\Desktop\New folder (2)\student-result\students\views.py", line 630, in student_marks_view
    years = [convert_year_to_thai(str(y)) for y in range(current_year, current_year - 10, -1)]
            ^^^^^^^^^^^^^^^^^^^^^^^^^^^^^^^^^^^^^^^^^^^^^^^^^^^^^^^^^^^^^^^^^^^^^^^^^^^^^^^^^^
  File "C:\Users\Sulaiman\Desktop\New folder (2)\student-result\students\views.py", line 630, in <listcomp>
    years = [convert_year_to_thai(str(y)) for y in range(current_year, current_year - 10, -1)]
             ^^^^^^^^^^^^^^^^^^^^
NameError: name 'convert_year_to_thai' is not defined
"GET /ingr_student HTTP/1.1" 500 84007
Internal Server Error: /ingr_student
Traceback (most recent call last):
  File "C:\Users\Sulaiman\AppData\Local\Programs\Python\Python311\Lib\site-packages\django\core\handlers\exception.py", line 55, in inner
    response = get_response(request)
               ^^^^^^^^^^^^^^^^^^^^^
  File "C:\Users\Sulaiman\AppData\Local\Programs\Python\Python311\Lib\site-packages\django\core\handlers\base.py", line 197, in _get_response
    response = wrapped_callback(request, *callback_args, **callback_kwargs)
               ^^^^^^^^^^^^^^^^^^^^^^^^^^^^^^^^^^^^^^^^^^^^^^^^^^^^^^^^^^^^
  File "C:\Users\Sulaiman\Desktop\New folder (2)\student-result\students\views.py", line 630, in student_marks_view
    years = [convert_year_to_thai(str(y)) for y in range(current_year, current_year - 10, -1)]
            ^^^^^^^^^^^^^^^^^^^^^^^^^^^^^^^^^^^^^^^^^^^^^^^^^^^^^^^^^^^^^^^^^^^^^^^^^^^^^^^^^^
  File "C:\Users\Sulaiman\Desktop\New folder (2)\student-result\students\views.py", line 630, in <listcomp>
    years = [convert_year_to_thai(str(y)) for y in range(current_year, current_year - 10, -1)]
             ^^^^^^^^^^^^^^^^^^^^
NameError: name 'convert_year_to_thai' is not defined
"GET /ingr_student HTTP/1.1" 500 84007
Internal Server Error: /ingr_student
Traceback (most recent call last):
  File "C:\Users\Sulaiman\AppData\Local\Programs\Python\Python311\Lib\site-packages\django\core\handlers\exception.py", line 55, in inner
    response = get_response(request)
               ^^^^^^^^^^^^^^^^^^^^^
  File "C:\Users\Sulaiman\AppData\Local\Programs\Python\Python311\Lib\site-packages\django\core\handlers\base.py", line 197, in _get_response
    response = wrapped_callback(request, *callback_args, **callback_kwargs)
               ^^^^^^^^^^^^^^^^^^^^^^^^^^^^^^^^^^^^^^^^^^^^^^^^^^^^^^^^^^^^
  File "C:\Users\Sulaiman\Desktop\New folder (2)\student-result\students\views.py", line 630, in student_marks_view
    years = [convert_year_to_thai(str(y)) for y in range(current_year, current_year - 10, -1)]
            ^^^^^^^^^^^^^^^^^^^^^^^^^^^^^^^^^^^^^^^^^^^^^^^^^^^^^^^^^^^^^^^^^^^^^^^^^^^^^^^^^^
  File "C:\Users\Sulaiman\Desktop\New folder (2)\student-result\students\views.py", line 630, in <listcomp>
    years = [convert_year_to_thai(str(y)) for y in range(current_year, current_year - 10, -1)]
             ^^^^^^^^^^^^^^^^^^^^
NameError: name 'convert_year_to_thai' is not defined
"GET /ingr_student HTTP/1.1" 500 84007
Internal Server Error: /ingr_student
Traceback (most recent call last):
  File "C:\Users\Sulaiman\AppData\Local\Programs\Python\Python311\Lib\site-packages\django\core\handlers\exception.py", line 55, in inner
    response = get_response(request)
               ^^^^^^^^^^^^^^^^^^^^^
  File "C:\Users\Sulaiman\AppData\Local\Programs\Python\Python311\Lib\site-packages\django\core\handlers\base.py", line 197, in _get_response
    response = wrapped_callback(request, *callback_args, **callback_kwargs)
               ^^^^^^^^^^^^^^^^^^^^^^^^^^^^^^^^^^^^^^^^^^^^^^^^^^^^^^^^^^^^
  File "C:\Users\Sulaiman\Desktop\New folder (2)\student-result\students\views.py", line 630, in student_marks_view
    years = [convert_year_to_thai(str(y)) for y in range(current_year, current_year - 10, -1)]
            ^^^^^^^^^^^^^^^^^^^^^^^^^^^^^^^^^^^^^^^^^^^^^^^^^^^^^^^^^^^^^^^^^^^^^^^^^^^^^^^^^^
  File "C:\Users\Sulaiman\Desktop\New folder (2)\student-result\students\views.py", line 630, in <listcomp>
    years = [convert_year_to_thai(str(y)) for y in range(current_year, current_year - 10, -1)]
             ^^^^^^^^^^^^^^^^^^^^
NameError: name 'convert_year_to_thai' is not defined
"GET /ingr_student HTTP/1.1" 500 84007
Internal Server Error: /ingr_student
Traceback (most recent call last):
  File "C:\Users\Sulaiman\AppData\Local\Programs\Python\Python311\Lib\site-packages\django\core\handlers\exception.py", line 55, in inner
    response = get_response(request)
               ^^^^^^^^^^^^^^^^^^^^^
  File "C:\Users\Sulaiman\AppData\Local\Programs\Python\Python311\Lib\site-packages\django\core\handlers\base.py", line 197, in _get_response
    response = wrapped_callback(request, *callback_args, **callback_kwargs)
               ^^^^^^^^^^^^^^^^^^^^^^^^^^^^^^^^^^^^^^^^^^^^^^^^^^^^^^^^^^^^
  File "C:\Users\Sulaiman\Desktop\New folder (2)\student-result\students\views.py", line 630, in student_marks_view
    years = [convert_year_to_thai(str(y)) for y in range(current_year, current_year - 10, -1)]
            ^^^^^^^^^^^^^^^^^^^^^^^^^^^^^^^^^^^^^^^^^^^^^^^^^^^^^^^^^^^^^^^^^^^^^^^^^^^^^^^^^^
  File "C:\Users\Sulaiman\Desktop\New folder (2)\student-result\students\views.py", line 630, in <listcomp>
    years = [convert_year_to_thai(str(y)) for y in range(current_year, current_year - 10, -1)]
             ^^^^^^^^^^^^^^^^^^^^
NameError: name 'convert_year_to_thai' is not defined
"GET /ingr_student HTTP/1.1" 500 84007
Internal Server Error: /ingr_student
Traceback (most recent call last):
  File "C:\Users\Sulaiman\AppData\Local\Programs\Python\Python311\Lib\site-packages\django\core\handlers\exception.py", line 55, in inner
    response = get_response(request)
               ^^^^^^^^^^^^^^^^^^^^^
  File "C:\Users\Sulaiman\AppData\Local\Programs\Python\Python311\Lib\site-packages\django\core\handlers\base.py", line 197, in _get_response
    response = wrapped_callback(request, *callback_args, **callback_kwargs)
               ^^^^^^^^^^^^^^^^^^^^^^^^^^^^^^^^^^^^^^^^^^^^^^^^^^^^^^^^^^^^
  File "C:\Users\Sulaiman\Desktop\New folder (2)\student-result\students\views.py", line 630, in student_marks_view
    years = [convert_year_to_thai(str(y)) for y in range(current_year, current_year - 10, -1)]
            ^^^^^^^^^^^^^^^^^^^^^^^^^^^^^^^^^^^^^^^^^^^^^^^^^^^^^^^^^^^^^^^^^^^^^^^^^^^^^^^^^^
  File "C:\Users\Sulaiman\Desktop\New folder (2)\student-result\students\views.py", line 630, in <listcomp>
    years = [convert_year_to_thai(str(y)) for y in range(current_year, current_year - 10, -1)]
             ^^^^^^^^^^^^^^^^^^^^
NameError: name 'convert_year_to_thai' is not defined
"GET /ingr_student HTTP/1.1" 500 84007
Internal Server Error: /ingr_student
Traceback (most recent call last):
  File "C:\Users\Sulaiman\AppData\Local\Programs\Python\Python311\Lib\site-packages\django\core\handlers\exception.py", line 55, in inner
    response = get_response(request)
               ^^^^^^^^^^^^^^^^^^^^^
  File "C:\Users\Sulaiman\AppData\Local\Programs\Python\Python311\Lib\site-packages\django\core\handlers\base.py", line 197, in _get_response
    response = wrapped_callback(request, *callback_args, **callback_kwargs)
               ^^^^^^^^^^^^^^^^^^^^^^^^^^^^^^^^^^^^^^^^^^^^^^^^^^^^^^^^^^^^
  File "C:\Users\Sulaiman\Desktop\New folder (2)\student-result\students\views.py", line 630, in student_marks_view
    years = [convert_year_to_thai(str(y)) for y in range(current_year, current_year - 10, -1)]
            ^^^^^^^^^^^^^^^^^^^^^^^^^^^^^^^^^^^^^^^^^^^^^^^^^^^^^^^^^^^^^^^^^^^^^^^^^^^^^^^^^^
  File "C:\Users\Sulaiman\Desktop\New folder (2)\student-result\students\views.py", line 630, in <listcomp>
    years = [convert_year_to_thai(str(y)) for y in range(current_year, current_year - 10, -1)]
             ^^^^^^^^^^^^^^^^^^^^
NameError: name 'convert_year_to_thai' is not defined
"GET /ingr_student HTTP/1.1" 500 83660
